Process ForkPoolWorker-4:
Traceback (most recent call last):
  File "/home/ubuntu/anaconda3/lib/python3.6/multiprocessing/pool.py", line 125, in worker
    put((job, i, result))
  File "/home/ubuntu/anaconda3/lib/python3.6/multiprocessing/queues.py", line 354, in put
    self._writer.send_bytes(obj)
  File "/home/ubuntu/anaconda3/lib/python3.6/multiprocessing/connection.py", line 200, in send_bytes
    self._send_bytes(m[offset:offset + size])
  File "/home/ubuntu/anaconda3/lib/python3.6/multiprocessing/connection.py", line 404, in _send_bytes
    self._send(header + buf)
  File "/home/ubuntu/anaconda3/lib/python3.6/multiprocessing/connection.py", line 368, in _send
    n = write(self._handle, buf)
BrokenPipeError: [Errno 32] Broken pipe

During handling of the above exception, another exception occurred:

Traceback (most recent call last):
  File "/home/ubuntu/anaconda3/lib/python3.6/multiprocessing/process.py", line 249, in _bootstrap
    self.run()
  File "/home/ubuntu/anaconda3/lib/python3.6/multiprocessing/process.py", line 93, in run
    self._target(*self._args, **self._kwargs)
  File "/home/ubuntu/anaconda3/lib/python3.6/multiprocessing/pool.py", line 130, in worker
    put((job, i, (False, wrapped)))
  File "/home/ubuntu/anaconda3/lib/python3.6/multiprocessing/queues.py", line 354, in put
    self._writer.send_bytes(obj)
  File "/home/ubuntu/anaconda3/lib/python3.6/multiprocessing/connection.py", line 200, in send_bytes
    self._send_bytes(m[offset:offset + size])
  File "/home/ubuntu/anaconda3/lib/python3.6/multiprocessing/connection.py", line 404, in _send_bytes
    self._send(header + buf)
  File "/home/ubuntu/anaconda3/lib/python3.6/multiprocessing/connection.py", line 368, in _send
    n = write(self._handle, buf)
BrokenPipeError: [Errno 32] Broken pipe
Process ForkPoolWorker-5:
Traceback (most recent call last):
  File "/home/ubuntu/anaconda3/lib/python3.6/multiprocessing/pool.py", line 125, in worker
    put((job, i, result))
  File "/home/ubuntu/anaconda3/lib/python3.6/multiprocessing/queues.py", line 354, in put
    self._writer.send_bytes(obj)
  File "/home/ubuntu/anaconda3/lib/python3.6/multiprocessing/connection.py", line 200, in send_bytes
    self._send_bytes(m[offset:offset + size])
  File "/home/ubuntu/anaconda3/lib/python3.6/multiprocessing/connection.py", line 404, in _send_bytes
    self._send(header + buf)
  File "/home/ubuntu/anaconda3/lib/python3.6/multiprocessing/connection.py", line 368, in _send
    n = write(self._handle, buf)
BrokenPipeError: [Errno 32] Broken pipe

During handling of the above exception, another exception occurred:

Traceback (most recent call last):
  File "/home/ubuntu/anaconda3/lib/python3.6/multiprocessing/process.py", line 249, in _bootstrap
    self.run()
  File "/home/ubuntu/anaconda3/lib/python3.6/multiprocessing/process.py", line 93, in run
    self._target(*self._args, **self._kwargs)
  File "/home/ubuntu/anaconda3/lib/python3.6/multiprocessing/pool.py", line 130, in worker
    put((job, i, (False, wrapped)))
  File "/home/ubuntu/anaconda3/lib/python3.6/multiprocessing/queues.py", line 354, in put
    self._writer.send_bytes(obj)
  File "/home/ubuntu/anaconda3/lib/python3.6/multiprocessing/connection.py", line 200, in send_bytes
    self._send_bytes(m[offset:offset + size])
  File "/home/ubuntu/anaconda3/lib/python3.6/multiprocessing/connection.py", line 404, in _send_bytes
    self._send(header + buf)
  File "/home/ubuntu/anaconda3/lib/python3.6/multiprocessing/connection.py", line 368, in _send
    n = write(self._handle, buf)
BrokenPipeError: [Errno 32] Broken pipe
Process ForkPoolWorker-6:
Traceback (most recent call last):
  File "/home/ubuntu/anaconda3/lib/python3.6/multiprocessing/pool.py", line 125, in worker
    put((job, i, result))
  File "/home/ubuntu/anaconda3/lib/python3.6/multiprocessing/queues.py", line 354, in put
    self._writer.send_bytes(obj)
  File "/home/ubuntu/anaconda3/lib/python3.6/multiprocessing/connection.py", line 200, in send_bytes
    self._send_bytes(m[offset:offset + size])
  File "/home/ubuntu/anaconda3/lib/python3.6/multiprocessing/connection.py", line 404, in _send_bytes
    self._send(header + buf)
  File "/home/ubuntu/anaconda3/lib/python3.6/multiprocessing/connection.py", line 368, in _send
    n = write(self._handle, buf)
BrokenPipeError: [Errno 32] Broken pipe

During handling of the above exception, another exception occurred:

Traceback (most recent call last):
  File "/home/ubuntu/anaconda3/lib/python3.6/multiprocessing/process.py", line 249, in _bootstrap
    self.run()
  File "/home/ubuntu/anaconda3/lib/python3.6/multiprocessing/process.py", line 93, in run
    self._target(*self._args, **self._kwargs)
  File "/home/ubuntu/anaconda3/lib/python3.6/multiprocessing/pool.py", line 130, in worker
    put((job, i, (False, wrapped)))
  File "/home/ubuntu/anaconda3/lib/python3.6/multiprocessing/queues.py", line 354, in put
    self._writer.send_bytes(obj)
  File "/home/ubuntu/anaconda3/lib/python3.6/multiprocessing/connection.py", line 200, in send_bytes
    self._send_bytes(m[offset:offset + size])
  File "/home/ubuntu/anaconda3/lib/python3.6/multiprocessing/connection.py", line 404, in _send_bytes
    self._send(header + buf)
  File "/home/ubuntu/anaconda3/lib/python3.6/multiprocessing/connection.py", line 368, in _send
    n = write(self._handle, buf)
BrokenPipeError: [Errno 32] Broken pipe
Process ForkPoolWorker-8:
Traceback (most recent call last):
  File "/home/ubuntu/anaconda3/lib/python3.6/multiprocessing/pool.py", line 125, in worker
    put((job, i, result))
  File "/home/ubuntu/anaconda3/lib/python3.6/multiprocessing/queues.py", line 354, in put
    self._writer.send_bytes(obj)
  File "/home/ubuntu/anaconda3/lib/python3.6/multiprocessing/connection.py", line 200, in send_bytes
    self._send_bytes(m[offset:offset + size])
  File "/home/ubuntu/anaconda3/lib/python3.6/multiprocessing/connection.py", line 404, in _send_bytes
    self._send(header + buf)
  File "/home/ubuntu/anaconda3/lib/python3.6/multiprocessing/connection.py", line 368, in _send
    n = write(self._handle, buf)
BrokenPipeError: [Errno 32] Broken pipe

During handling of the above exception, another exception occurred:

Traceback (most recent call last):
  File "/home/ubuntu/anaconda3/lib/python3.6/multiprocessing/process.py", line 249, in _bootstrap
    self.run()
  File "/home/ubuntu/anaconda3/lib/python3.6/multiprocessing/process.py", line 93, in run
    self._target(*self._args, **self._kwargs)
  File "/home/ubuntu/anaconda3/lib/python3.6/multiprocessing/pool.py", line 130, in worker
    put((job, i, (False, wrapped)))
  File "/home/ubuntu/anaconda3/lib/python3.6/multiprocessing/queues.py", line 354, in put
    self._writer.send_bytes(obj)
  File "/home/ubuntu/anaconda3/lib/python3.6/multiprocessing/connection.py", line 200, in send_bytes
    self._send_bytes(m[offset:offset + size])
  File "/home/ubuntu/anaconda3/lib/python3.6/multiprocessing/connection.py", line 404, in _send_bytes
    self._send(header + buf)
  File "/home/ubuntu/anaconda3/lib/python3.6/multiprocessing/connection.py", line 368, in _send
    n = write(self._handle, buf)
BrokenPipeError: [Errno 32] Broken pipe
Traceback (most recent call last):
  File "PSOMain.py", line 1, in <module>
    import numpy as np
ImportError: No module named numpy
Traceback (most recent call last):
  File "PSOMain.py", line 1, in <module>
    import numpy as np
ImportError: No module named numpy
Traceback (most recent call last):
  File "PSOMain.py", line 208, in <module>
    pmin, fmin, nrounds = pso_algo_par(f, s, bounds, params, maxrounds, tol, nochange)
  File "PSOMain.py", line 112, in pso_algo_par
    results_0 = pool.starmap(point_update, inputs)
AttributeError: 'Pool' object has no attribute 'starmap'
Traceback (most recent call last):
  File "PSOMain.py", line 206, in <module>
    pmin, fmin, nrounds = pso_algo_par(f, s, bounds, params, maxrounds, tol, nochange)
  File "PSOMain.py", line 110, in pso_algo_par
    results_0 = pool.starmap(point_update, inputs)
AttributeError: 'Pool' object has no attribute 'starmap'
